Workbook
Name CAMBIO_DOLAR: #REF!
Name CFR_REAL: #REF!
Name FOB_DOLAR: #REF!
Name FOB_REAL: #REF!
Name FRETE_INTERNACIONAL_DOLAR: #REF!

Sheet INVOICE
A1: No. | B1: Descriptions | C1: Brand | D1: QTY TON | E1: NCM | F1: VALOR UNIT | G1: VALOR TOTAL | H1: PESO TOTAL | I1: VALOR UNIT DEC | J1: VALOR TOTAL DEC | K1: VALOR UNIT ROYALTIES | L1: VALOR TOTAL ROYALTIES | M1: % ROYALTIES
A3: 1 | B3: Clavo con cabeza 10 x 10 | C3: 1 x 18 | D3: 1 | E3: 7317.00.90 | F3: 1180 | G3: =F3*D3 -> 1180 | H3: =D3*1000 -> 1000 | I3: =F3 -> 1180 | J3: =I3*D3 -> 1180 | K3: =F3-I3 -> 0 | L3: =K3*D3 -> 0
A4: 2 | B4: Clavo con cabeza 15 x 15 | C4: 1 1/4 x 13 | D4: 1 | E4: 7317.00.90 | F4: 1060 | G4: =F4*D4 -> 1060 | H4: =D4*1000 -> 1000 | I4: =F4 -> 1060 | J4: =I4*D4 -> 1060 | K4: =F4-I4 -> 0 | L4: =K4*D4 -> 0
A5: 3 | B5: Clavo con cabeza 13 x 15 | C5: 1 1/4 x15 | D5: 1 | E5: 7317.00.90 | F5: 1120 | G5: =F5*D5 -> 1120 | H5: =D5*1000 -> 1000 | I5: =F5 -> 1120 | J5: =I5*D5 -> 1120 | K5: =F5-I5 -> 0 | L5: =K5*D5 -> 0
A6: 4 | B6: Clavo con cabeza 15 x 18 | C6: 1 1/2 x 13 | D6: 1 | E6: 7317.00.90 | F6: 1060 | G6: =F6*D6 -> 1060 | H6: =D6*1000 -> 1000 | I6: =F6 -> 1060 | J6: =I6*D6 -> 1060 | K6: =F6-I6 -> 0 | L6: =K6*D6 -> 0
A7: 5 | B7: Clavo con cabeza 17 x 21 | C7: 2 x 11 | D7: 1 | E7: 7317.00.90 | F7: 970 | G7: =F7*D7 -> 970 | H7: =D7*1000 -> 1000 | I7: =F7 -> 970 | J7: =I7*D7 -> 970 | K7: =F7-I7 -> 0 | L7: =K7*D7 -> 0
A8: 6 | B8: Clavo sin cabeza 17 x 21 | C8: 2 x 11 s/c | D8: 1 | E8: 7317.00.90 | F8: 970 | G8: =F8*D8 -> 970 | H8: =D8*1000 -> 1000 | I8: =F8 -> 970 | J8: =I8*D8 -> 970 | K8: =F8-I8 -> 0 | L8: =K8*D8 -> 0
A9: 7 | B9: Clavo con cabeza 15 x 21 | C9: 2 x 13 | D9: 1 | E9: 7317.00.90 | F9: 1060 | G9: =F9*D9 -> 1060 | H9: =D9*1000 -> 1000 | I9: =F9 -> 1060 | J9: =I9*D9 -> 1060 | K9: =F9-I9 -> 0 | L9: =K9*D9 -> 0
A10: 8 | B10: Clavo con cabeza 17 x 27 | C10: 2 1/2 x 11 | D10: 1 | E10: 7317.00.90 | F10: 970 | G10: =F10*D10 -> 970 | H10: =D10*1000 -> 1000 | I10: =F10 -> 970 | J10: =I10*D10 -> 970 | K10: =F10-I10 -> 0 | L10: =K10*D10 -> 0
A11: 9 | B11: Clavo con cabeza 18 x 27 | C11: 2 1/2 x 10 | D11: 1 | E11: 7317.00.90 | F11: 970 | G11: =F11*D11 -> 970 | H11: =D11*1000 -> 1000 | I11: =F11 -> 970 | J11: =I11*D11 -> 970 | K11: =F11-I11 -> 0 | L11: =K11*D11 -> 0
A12: 10 | B12: Clavo con cabeza 18 x 36 | C12: 3 1/4 x 10 | D12: 1 | E12: 7317.00.90 | F12: 970 | G12: =F12*D12 -> 970 | H12: =D12*1000 -> 1000 | I12: =F12 -> 970 | J12: =I12*D12 -> 970 | K12: =F12-I12 -> 0 | L12: =K12*D12 -> 0
A13: 11 | B13: Clavo con cabeza 19 x 36 | C13: 3 1/4 x 9 | D13: 1 | E13: 7317.00.90 | F13: 970 | G13: =F13*D13 -> 970 | H13: =D13*1000 -> 1000 | I13: =F13 -> 970 | J13: =I13*D13 -> 970 | K13: =F13-I13 -> 0 | L13: =K13*D13 -> 0
B14: TOTAL | D14: =SUM(D3:D13) -> 11
G15: =SUM(G3:G14) -> 11300 | H15: =SUM(H3:H13) -> 11000 | J15: =SUM(J3:J14) -> 11300 | L15: =SUM(L3:L14) -> 0
G69: =SUM(G3:G68) -> 22600

Sheet CUSTO MERCADORIA - IMP. PRÓPRIA
B2: ESTIMATIVA DE IMPORTAÇÃO
B5: Descrição | C5: Moeda EX | D5: Valor | E5: Moeda R$ | G5: Peso Bruto | H5: 0
B6: Valor Fob | C6: USD | D6: =INVOICE!J15 -> 11300 | E6: =D6*H7 -> 61924 | G6: Peso Liquido | H6: =K38 -> 11000
B7: Valor Frete | C7: USD | D7: =2550+(D6*0.3%) -> 2583.9 | E7: =D7*H7 -> 14159.772 | G7: Taxa dólar | H7: 5.48
B8: Seguro | C8: USD | D8: 0 | E8: =D8*H7 -> 0 | G8: SISCOMEX | H8: 154.23
B9: Valor ADU | C9: USD | D9: =SUM(D6:D8) -> 13883.9 | E9: =SUM(E6:E8) -> 76083.772 | G9: AFRMM | H9: 0
B12: Demais Despesas
B13: Liberação | E13: 0
B14: Armazenagem | E14: 0
B15: Frete interno | E15: 0
B16: Comissão Despacho Aduaneiro | E16: 3000
B17: Taxa de Expediente | E17: 1000
E18: 0
B19: Total | E19: =SUM(E13:E18) -> 4000
B22: Pacote Logístico - Frete Rodoviário | E22: 0
B23: Royalties | E23: =INVOICE!L15*H7 -> 0
B25: CUSTO DE IMPORTAÇÃO | AR25: CUSTO LÍQUIDO E VENDA DO IMPORTADOR | BD25: CUSTO LÍQUIDO DO COMPRADOR
B26: ADIÇÃO | C26: ITEM | D26: CÓDIGO | E26: QUANTIDADE | F26: UN. | G26: DESCRIÇÃO | H26: NCM | I26: VALOR UNITÁRIO | J26: VALOR TOTAL | K26: PESO | L26: % PESO | M26: Valor FOB R$ | N26: FRETE USD | O26: FRETE | P26: SEGURO | Q26: VLR ADUANEIRO USD | R26: VLR ADUANEIRO R$ | T26: AFRMM | U26: SISCOMEX | V26: Antidumping unitário/KG | W26: Antidumping | X26: DEMAIS DESPESAS | Y26: % II | Z26: VALOR II | AA26: MERCADORIA USD | AB26: MERCADORIA UNIT | AD26: BASE IPI | AE26: % IPI | AF26: VALOR IPI-IMP | AG26: % PIS | AH26: VALOR PIS-IMP | AI26: % COFINS | AJ26: VALOR COFINS- IMP | AK26: CRÉDITO COFINS-IMP | AL26: BASE ICMS ANTECIPADO | AM26: % ICMS | AN26: VALOR ICMS-ANTECIPADO | AO26: CUSTO TOTAL | AP26: CUSTO UNIT. | AR26: CUSTO LÍQUIDO IMPORTAÇÃO | AS26: CUSTO LÍQUIDO TOTAL | AT26: CUSTO UNIT. LIQ. | AU26: MKP | AV26: VALOR DOS PRODUTOS | AW26: % ICMS | AX26: ICMS | AY26: IPI | AZ26: ICMS ST | BA26: TOTAL NF VENDA | BB26: VALOR UNITÁRIO C/ IPI E ICMS ST | BD26: ICMS ST ENTRADA SP | BE26: CUSTO LÍQUIDO TOTAL | BF26: CUSTO UNIT. LIQ.
D27: =INVOICE!C3 -> 1 x 18 | E27: =INVOICE!D3 -> 1 | F27: TON | G27: =INVOICE!B3 -> Clavo con cabeza 10 x 10 | H27: =INVOICE!E3 -> 7317.00.90 | I27: =INVOICE!I3 -> 1180 | J27: =E27*I27 -> 1180 | K27: =INVOICE!H3 -> 1000 | L27: =K27/$K$38 -> 0.090909091 | M27: =J27*$H$7 -> 6466.4 | N27: =$D$7*L27 -> 234.9 | O27: =$E$7*L27 -> 1287.252 | P27: =$E$8*L27 -> 0 | Q27: =J27+N27 -> 1414.9 | R27: =M27+O27+P27 -> 7753.652 | T27: =$H$9*L27 -> 0 | U27: =$H$8*L27 -> 14.020909 | V27: 0 | W27: 0 | X27: =$E$19*L27 -> 363.63636 | Y27: 0.25 | Z27: =R27*Y27 -> 1938.413 | AA27: =J27+N27 -> 1414.9 | AB27: =AA27/E27 -> 1414.9 | AD27: =R27+Z27 -> 9692.065 | AE27: 0.065 | AF27: =AD27*AE27 -> 629.98423 | AG27: 0.021 | AH27: =(R27*AG27) -> 162.82669 | AI27: 0.0965 | AJ27: =(R27*AI27) -> 748.22742 | AK27: =R27*9.65% -> 748.22742 | AL27: =(R27+U27+Z27+AF27+AH27+AJ27+W27)/0.96 -> 11715.754 | AM27: 0.01 | AN27: =AL27*AM27 -> 117.15754 | AO27: =R27+T27+U27+X27+Z27+AF27+AH27+AJ27+W27+AN27 -> 11727.918 | AP27: =AO27/E27 -> 11727.918 | AR27: =AO27-AF27-AH27-AK27-AN27 -> 10069.722 | AS27: =AR27+(E$22*L27)+($E$23*L27) -> 10069.722 | AT27: =AS27/E27 -> 10069.722 | AU27: ='EST. DE CUSTO - IMP. PRÓPRIA'!$H$68 -> 0.65174242 | AV27: =AS27/AU27 -> 15450.463 | AW27: ='EST. DE CUSTO - IMP. PRÓPRIA'!$F$63 -> 0.04 | AX27: =AV27*AW27 -> 618.01852 | AY27: =AV27*AE27 -> 1004.2801 | AZ27: 0 | BA27: =AV27+AY27+AZ27 -> 16454.743 | BB27: =BA27/E27 -> 16454.743 | BD27: 0 | BE27: =BA27+BD27 -> 16454.743 | BF27: =BE27/E27 -> 16454.743
D28: =INVOICE!C4 -> 1 1/4 x 13 | E28: =INVOICE!D4 -> 1 | F28: TON | G28: =INVOICE!B4 -> Clavo con cabeza 15 x 15 | H28: =INVOICE!E4 -> 7317.00.90 | I28: =INVOICE!I4 -> 1060 | J28: =E28*I28 -> 1060 | K28: =INVOICE!H4 -> 1000 | L28: =K28/$H$6 -> 0.090909091 | M28: =J28*$H$7 -> 5808.8 | N28: =$D$7*L28 -> 234.9 | O28: =$E$7*L28 -> 1287.252 | P28: =$E$8*L28 -> 0 | Q28: =J28+N28 -> 1294.9 | R28: =M28+O28+P28 -> 7096.052 | T28: =$H$9*L28 -> 0 | U28: =$H$8*L28 -> 14.020909 | V28: 0 | W28: 0 | X28: =$E$19*L28 -> 363.63636 | Y28: 0.25 | Z28: =R28*Y28 -> 1774.013 | AA28: =J28+N28 -> 1294.9 | AB28: =AA28/E28 -> 1294.9 | AD28: =R28+Z28 -> 8870.065 | AE28: 0.065 | AF28: =AD28*AE28 -> 576.55423 | AG28: 0.021 | AH28: =(R28*AG28) -> 149.01709 | AI28: 0.0965 | AJ28: =(R28*AI28) -> 684.76902 | AK28: =R28*9.65% -> 684.76902 | AL28: =(R28+U28+Z28+AF28+AH28+AJ28+W28)/0.96 -> 10723.361 | AM28: 0.01 | AN28: =AL28*AM28 -> 107.23361 | AO28: =R28+T28+U28+X28+Z28+AF28+AH28+AJ28+W28+AN28 -> 10765.296 | AP28: =AO28/E28 -> 10765.296 | AR28: =AO28-AF28-AH28-AK28-AN28 -> 9247.7223 | AS28: =AR28+(E$22*L28)+($E$23*L28) -> 9247.7223 | AT28: =AS28/E28 -> 9247.7223 | AU28: ='EST. DE CUSTO - IMP. PRÓPRIA'!$H$68 -> 0.65174242 | AV28: =AS28/AU28 -> 14189.229 | AW28: ='EST. DE CUSTO - IMP. PRÓPRIA'!$F$63 -> 0.04 | AX28: =AV28*AW28 -> 567.56915 | AY28: =AV28*AE28 -> 922.29986 | AZ28: 0 | BA28: =AV28+AY28+AZ28 -> 15111.529 | BB28: =BA28/E28 -> 15111.529 | BD28: 0 | BE28: =BA28+BD28 -> 15111.529 | BF28: =BE28/E28 -> 15111.529
D29: =INVOICE!C5 -> 1 1/4 x15 | E29: =INVOICE!D5 -> 1 | F29: TON | G29: =INVOICE!B5 -> Clavo con cabeza 13 x 15 | H29: =INVOICE!E5 -> 7317.00.90 | I29: =INVOICE!I5 -> 1120 | J29: =E29*I29 -> 1120 | K29: =INVOICE!H5 -> 1000 | L29: =K29/$H$6 -> 0.090909091 | M29: =J29*$H$7 -> 6137.6 | N29: =$D$7*L29 -> 234.9 | O29: =$E$7*L29 -> 1287.252 | P29: =$E$8*L29 -> 0 | Q29: =J29+N29 -> 1354.9 | R29: =M29+O29+P29 -> 7424.852 | T29: =$H$9*L29 -> 0 | U29: =$H$8*L29 -> 14.020909 | V29: 0 | W29: 0 | X29: =$E$19*L29 -> 363.63636 | Y29: 0.25 | Z29: =R29*Y29 -> 1856.213 | AA29: =J29+N29 -> 1354.9 | AB29: =AA29/E29 -> 1354.9 | AD29: =R29+Z29 -> 9281.065 | AE29: 0.065 | AF29: =AD29*AE29 -> 603.26923 | AG29: 0.021 | AH29: =(R29*AG29) -> 155.92189 | AI29: 0.0965 | AJ29: =(R29*AI29) -> 716.49822 | AK29: =R29*9.65% -> 716.49822 | AL29: =(R29+U29+Z29+AF29+AH29+AJ29+W29)/0.96 -> 11219.558 | AM29: 0.01 | AN29: =AL29*AM29 -> 112.19558 | AO29: =R29+T29+U29+X29+Z29+AF29+AH29+AJ29+W29+AN29 -> 11246.607 | AP29: =AO29/E29 -> 11246.607 | AR29: =AO29-AF29-AH29-AK29-AN29 -> 9658.7223 | AS29: =AR29+(E$22*L29)+($E$23*L29) -> 9658.7223 | AT29: =AS29/E29 -> 9658.7223 | AU29: ='EST. DE CUSTO - IMP. PRÓPRIA'!$H$68 -> 0.65174242 | AV29: =AS29/AU29 -> 14819.846 | AW29: ='EST. DE CUSTO - IMP. PRÓPRIA'!$F$63 -> 0.04 | AX29: =AV29*AW29 -> 592.79383 | AY29: =AV29*AE29 -> 963.28998 | AZ29: 0 | BA29: =AV29+AY29+AZ29 -> 15783.136 | BB29: =BA29/E29 -> 15783.136 | BD29: 0 | BE29: =BA29+BD29 -> 15783.136 | BF29: =BE29/E29 -> 15783.136
D30: =INVOICE!C6 -> 1 1/2 x 13 | E30: =INVOICE!D6 -> 1 | F30: TON | G30: =INVOICE!B6 -> Clavo con cabeza 15 x 18 | H30: =INVOICE!E6 -> 7317.00.90 | I30: =INVOICE!I6 -> 1060 | J30: =E30*I30 -> 1060 | K30: =INVOICE!H6 -> 1000 | L30: =K30/$H$6 -> 0.090909091 | M30: =J30*$H$7 -> 5808.8 | N30: =$D$7*L30 -> 234.9 | O30: =$E$7*L30 -> 1287.252 | P30: =$E$8*L30 -> 0 | Q30: =J30+N30 -> 1294.9 | R30: =M30+O30+P30 -> 7096.052 | T30: =$H$9*L30 -> 0 | U30: =$H$8*L30 -> 14.020909 | V30: 0 | W30: 0 | X30: =$E$19*L30 -> 363.63636 | Y30: 0.25 | Z30: =R30*Y30 -> 1774.013 | AA30: =J30+N30 -> 1294.9 | AB30: =AA30/E30 -> 1294.9 | AD30: =R30+Z30 -> 8870.065 | AE30: 0.065 | AF30: =AD30*AE30 -> 576.55423 | AG30: 0.021 | AH30: =(R30*AG30) -> 149.01709 | AI30: 0.0965 | AJ30: =(R30*AI30) -> 684.76902 | AK30: =R30*9.65% -> 684.76902 | AL30: =(R30+U30+Z30+AF30+AH30+AJ30+W30)/0.96 -> 10723.361 | AM30: 0.01 | AN30: =AL30*AM30 -> 107.23361 | AO30: =R30+T30+U30+X30+Z30+AF30+AH30+AJ30+W30+AN30 -> 10765.296 | AP30: =AO30/E30 -> 10765.296 | AR30: =AO30-AF30-AH30-AK30-AN30 -> 9247.7223 | AS30: =AR30+(E$22*L30)+($E$23*L30) -> 9247.7223 | AT30: =AS30/E30 -> 9247.7223 | AU30: ='EST. DE CUSTO - IMP. PRÓPRIA'!$H$68 -> 0.65174242 | AV30: =AS30/AU30 -> 14189.229 | AW30: ='EST. DE CUSTO - IMP. PRÓPRIA'!$F$63 -> 0.04 | AX30: =AV30*AW30 -> 567.56915 | AY30: =AV30*AE30 -> 922.29986 | AZ30: 0 | BA30: =AV30+AY30+AZ30 -> 15111.529 | BB30: =BA30/E30 -> 15111.529 | BD30: 0 | BE30: =BA30+BD30 -> 15111.529 | BF30: =BE30/E30 -> 15111.529
D31: =INVOICE!C7 -> 2 x 11 | E31: =INVOICE!D7 -> 1 | F31: TON | G31: =INVOICE!B7 -> Clavo con cabeza 17 x 21 | H31: =INVOICE!E7 -> 7317.00.90 | I31: =INVOICE!I7 -> 970 | J31: =E31*I31 -> 970 | K31: =INVOICE!H7 -> 1000 | L31: =K31/$H$6 -> 0.090909091 | M31: =J31*$H$7 -> 5315.6 | N31: =$D$7*L31 -> 234.9 | O31: =$E$7*L31 -> 1287.252 | P31: =$E$8*L31 -> 0 | Q31: =J31+N31 -> 1204.9 | R31: =M31+O31+P31 -> 6602.852 | T31: =$H$9*L31 -> 0 | U31: =$H$8*L31 -> 14.020909 | V31: 0 | W31: 0 | X31: =$E$19*L31 -> 363.63636 | Y31: 0.25 | Z31: =R31*Y31 -> 1650.713 | AA31: =J31+N31 -> 1204.9 | AB31: =AA31/E31 -> 1204.9 | AD31: =R31+Z31 -> 8253.565 | AE31: 0.065 | AF31: =AD31*AE31 -> 536.48173 | AG31: 0.021 | AH31: =(R31*AG31) -> 138.65989 | AI31: 0.0965 | AJ31: =(R31*AI31) -> 637.17522 | AK31: =R31*9.65% -> 637.17522 | AL31: =(R31+U31+Z31+AF31+AH31+AJ31+W31)/0.96 -> 9979.0654 | AM31: 0.01 | AN31: =AL31*AM31 -> 99.790654 | AO31: =R31+T31+U31+X31+Z31+AF31+AH31+AJ31+W31+AN31 -> 10043.33 | AP31: =AO31/E31 -> 10043.33 | AR31: =AO31-AF31-AH31-AK31-AN31 -> 8631.2223 | AS31: =AR31+(E$22*L31)+($E$23*L31) -> 8631.2223 | AT31: =AS31/E31 -> 8631.2223 | AU31: ='EST. DE CUSTO - IMP. PRÓPRIA'!$H$68 -> 0.65174242 | AV31: =AS31/AU31 -> 13243.303 | AW31: ='EST. DE CUSTO - IMP. PRÓPRIA'!$F$63 -> 0.04 | AX31: =AV31*AW31 -> 529.73211 | AY31: =AV31*AE31 -> 860.81468 | AZ31: 0 | BA31: =AV31+AY31+AZ31 -> 14104.117 | BB31: =BA31/E31 -> 14104.117 | BD31: 0 | BE31: =BA31+BD31 -> 14104.117 | BF31: =BE31/E31 -> 14104.117
D32: =INVOICE!C8 -> 2 x 11 s/c | E32: =INVOICE!D8 -> 1 | F32: TON | G32: =INVOICE!B8 -> Clavo sin cabeza 17 x 21 | H32: =INVOICE!E8 -> 7317.00.90 | I32: =INVOICE!I8 -> 970 | J32: =E32*I32 -> 970 | K32: =INVOICE!H8 -> 1000 | L32: =K32/$H$6 -> 0.090909091 | M32: =J32*$H$7 -> 5315.6 | N32: =$D$7*L32 -> 234.9 | O32: =$E$7*L32 -> 1287.252 | P32: =$E$8*L32 -> 0 | Q32: =J32+N32 -> 1204.9 | R32: =M32+O32+P32 -> 6602.852 | T32: =$H$9*L32 -> 0 | U32: =$H$8*L32 -> 14.020909 | V32: 0 | W32: 0 | X32: =$E$19*L32 -> 363.63636 | Y32: 0.25 | Z32: =R32*Y32 -> 1650.713 | AA32: =J32+N32 -> 1204.9 | AB32: =AA32/E32 -> 1204.9 | AD32: =R32+Z32 -> 8253.565 | AE32: 0.065 | AF32: =AD32*AE32 -> 536.48173 | AG32: 0.021 | AH32: =(R32*AG32) -> 138.65989 | AI32: 0.0965 | AJ32: =(R32*AI32) -> 637.17522 | AK32: =R32*9.65% -> 637.17522 | AL32: =(R32+U32+Z32+AF32+AH32+AJ32+W32)/0.96 -> 9979.0654 | AM32: 0.01 | AN32: =AL32*AM32 -> 99.790654 | AO32: =R32+T32+U32+X32+Z32+AF32+AH32+AJ32+W32+AN32 -> 10043.33 | AP32: =AO32/E32 -> 10043.33 | AR32: =AO32-AF32-AH32-AK32-AN32 -> 8631.2223 | AS32: =AR32+(E$22*L32)+($E$23*L32) -> 8631.2223 | AT32: =AS32/E32 -> 8631.2223 | AU32: ='EST. DE CUSTO - IMP. PRÓPRIA'!$H$68 -> 0.65174242 | AV32: =AS32/AU32 -> 13243.303 | AW32: ='EST. DE CUSTO - IMP. PRÓPRIA'!$F$63 -> 0.04 | AX32: =AV32*AW32 -> 529.73211 | AY32: =AV32*AE32 -> 860.81468 | AZ32: 0 | BA32: =AV32+AY32+AZ32 -> 14104.117 | BB32: =BA32/E32 -> 14104.117 | BD32: 0 | BE32: =BA32+BD32 -> 14104.117 | BF32: =BE32/E32 -> 14104.117
D33: =INVOICE!C9 -> 2 x 13 | E33: =INVOICE!D9 -> 1 | F33: TON | G33: =INVOICE!B9 -> Clavo con cabeza 15 x 21 | H33: =INVOICE!E9 -> 7317.00.90 | I33: =INVOICE!I9 -> 1060 | J33: =E33*I33 -> 1060 | K33: =INVOICE!H9 -> 1000 | L33: =K33/$H$6 -> 0.090909091 | M33: =J33*$H$7 -> 5808.8 | N33: =$D$7*L33 -> 234.9 | O33: =$E$7*L33 -> 1287.252 | P33: =$E$8*L33 -> 0 | Q33: =J33+N33 -> 1294.9 | R33: =M33+O33+P33 -> 7096.052 | T33: =$H$9*L33 -> 0 | U33: =$H$8*L33 -> 14.020909 | V33: 0 | W33: 0 | X33: =$E$19*L33 -> 363.63636 | Y33: 0.25 | Z33: =R33*Y33 -> 1774.013 | AA33: =J33+N33 -> 1294.9 | AB33: =AA33/E33 -> 1294.9 | AD33: =R33+Z33 -> 8870.065 | AE33: 0.065 | AF33: =AD33*AE33 -> 576.55423 | AG33: 0.021 | AH33: =(R33*AG33) -> 149.01709 | AI33: 0.0965 | AJ33: =(R33*AI33) -> 684.76902 | AK33: =R33*9.65% -> 684.76902 | AL33: =(R33+U33+Z33+AF33+AH33+AJ33+W33)/0.96 -> 10723.361 | AM33: 0.01 | AN33: =AL33*AM33 -> 107.23361 | AO33: =R33+T33+U33+X33+Z33+AF33+AH33+AJ33+W33+AN33 -> 10765.296 | AP33: =AO33/E33 -> 10765.296 | AR33: =AO33-AF33-AH33-AK33-AN33 -> 9247.7223 | AS33: =AR33+(E$22*L33)+($E$23*L33) -> 9247.7223 | AT33: =AS33/E33 -> 9247.7223 | AU33: ='EST. DE CUSTO - IMP. PRÓPRIA'!$H$68 -> 0.65174242 | AV33: =AS33/AU33 -> 14189.229 | AW33: ='EST. DE CUSTO - IMP. PRÓPRIA'!$F$63 -> 0.04 | AX33: =AV33*AW33 -> 567.56915 | AY33: =AV33*AE33 -> 922.29986 | AZ33: 0 | BA33: =AV33+AY33+AZ33 -> 15111.529 | BB33: =BA33/E33 -> 15111.529 | BD33: 0 | BE33: =BA33+BD33 -> 15111.529 | BF33: =BE33/E33 -> 15111.529
D34: =INVOICE!C10 -> 2 1/2 x 11 | E34: =INVOICE!D10 -> 1 | F34: TON | G34: =INVOICE!B10 -> Clavo con cabeza 17 x 27 | H34: =INVOICE!E10 -> 7317.00.90 | I34: =INVOICE!I10 -> 970 | J34: =E34*I34 -> 970 | K34: =INVOICE!H10 -> 1000 | L34: =K34/$H$6 -> 0.090909091 | M34: =J34*$H$7 -> 5315.6 | N34: =$D$7*L34 -> 234.9 | O34: =$E$7*L34 -> 1287.252 | P34: =$E$8*L34 -> 0 | Q34: =J34+N34 -> 1204.9 | R34: =M34+O34+P34 -> 6602.852 | T34: =$H$9*L34 -> 0 | U34: =$H$8*L34 -> 14.020909 | V34: 0 | W34: 0 | X34: =$E$19*L34 -> 363.63636 | Y34: 0.25 | Z34: =R34*Y34 -> 1650.713 | AA34: =J34+N34 -> 1204.9 | AB34: =AA34/E34 -> 1204.9 | AD34: =R34+Z34 -> 8253.565 | AE34: 0.065 | AF34: =AD34*AE34 -> 536.48173 | AG34: 0.021 | AH34: =(R34*AG34) -> 138.65989 | AI34: 0.0965 | AJ34: =(R34*AI34) -> 637.17522 | AK34: =R34*9.65% -> 637.17522 | AL34: =(R34+U34+Z34+AF34+AH34+AJ34+W34)/0.96 -> 9979.0654 | AM34: 0.01 | AN34: =AL34*AM34 -> 99.790654 | AO34: =R34+T34+U34+X34+Z34+AF34+AH34+AJ34+W34+AN34 -> 10043.33 | AP34: =AO34/E34 -> 10043.33 | AR34: =AO34-AF34-AH34-AK34-AN34 -> 8631.2223 | AS34: =AR34+(E$22*L34)+($E$23*L34) -> 8631.2223 | AT34: =AS34/E34 -> 8631.2223 | AU34: ='EST. DE CUSTO - IMP. PRÓPRIA'!$H$68 -> 0.65174242 | AV34: =AS34/AU34 -> 13243.303 | AW34: ='EST. DE CUSTO - IMP. PRÓPRIA'!$F$63 -> 0.04 | AX34: =AV34*AW34 -> 529.73211 | AY34: =AV34*AE34 -> 860.81468 | AZ34: 0 | BA34: =AV34+AY34+AZ34 -> 14104.117 | BB34: =BA34/E34 -> 14104.117 | BD34: 0 | BE34: =BA34+BD34 -> 14104.117 | BF34: =BE34/E34 -> 14104.117
D35: =INVOICE!C11 -> 2 1/2 x 10 | E35: =INVOICE!D11 -> 1 | F35: TON | G35: =INVOICE!B11 -> Clavo con cabeza 18 x 27 | H35: =INVOICE!E11 -> 7317.00.90 | I35: =INVOICE!I11 -> 970 | J35: =E35*I35 -> 970 | K35: =INVOICE!H11 -> 1000 | L35: =K35/$H$6 -> 0.090909091 | M35: =J35*$H$7 -> 5315.6 | N35: =$D$7*L35 -> 234.9 | O35: =$E$7*L35 -> 1287.252 | P35: =$E$8*L35 -> 0 | Q35: =J35+N35 -> 1204.9 | R35: =M35+O35+P35 -> 6602.852 | T35: =$H$9*L35 -> 0 | U35: =$H$8*L35 -> 14.020909 | V35: 0 | W35: 0 | X35: =$E$19*L35 -> 363.63636 | Y35: 0.25 | Z35: =R35*Y35 -> 1650.713 | AA35: =J35+N35 -> 1204.9 | AB35: =AA35/E35 -> 1204.9 | AD35: =R35+Z35 -> 8253.565 | AE35: 0.065 | AF35: =AD35*AE35 -> 536.48173 | AG35: 0.021 | AH35: =(R35*AG35) -> 138.65989 | AI35: 0.0965 | AJ35: =(R35*AI35) -> 637.17522 | AK35: =R35*9.65% -> 637.17522 | AL35: =(R35+U35+Z35+AF35+AH35+AJ35+W35)/0.96 -> 9979.0654 | AM35: 0.01 | AN35: =AL35*AM35 -> 99.790654 | AO35: =R35+T35+U35+X35+Z35+AF35+AH35+AJ35+W35+AN35 -> 10043.33 | AP35: =AO35/E35 -> 10043.33 | AR35: =AO35-AF35-AH35-AK35-AN35 -> 8631.2223 | AS35: =AR35+(E$22*L35)+($E$23*L35) -> 8631.2223 | AT35: =AS35/E35 -> 8631.2223 | AU35: ='EST. DE CUSTO - IMP. PRÓPRIA'!$H$68 -> 0.65174242 | AV35: =AS35/AU35 -> 13243.303 | AW35: ='EST. DE CUSTO - IMP. PRÓPRIA'!$F$63 -> 0.04 | AX35: =AV35*AW35 -> 529.73211 | AY35: =AV35*AE35 -> 860.81468 | AZ35: 0 | BA35: =AV35+AY35+AZ35 -> 14104.117 | BB35: =BA35/E35 -> 14104.117 | BD35: 0 | BE35: =BA35+BD35 -> 14104.117 | BF35: =BE35/E35 -> 14104.117
D36: =INVOICE!C12 -> 3 1/4 x 10 | E36: =INVOICE!D12 -> 1 | F36: TON | G36: =INVOICE!B12 -> Clavo con cabeza 18 x 36 | H36: =INVOICE!E12 -> 7317.00.90 | I36: =INVOICE!I12 -> 970 | J36: =E36*I36 -> 970 | K36: =INVOICE!H12 -> 1000 | L36: =K36/$H$6 -> 0.090909091 | M36: =J36*$H$7 -> 5315.6 | N36: =$D$7*L36 -> 234.9 | O36: =$E$7*L36 -> 1287.252 | P36: =$E$8*L36 -> 0 | Q36: =J36+N36 -> 1204.9 | R36: =M36+O36+P36 -> 6602.852 | T36: =$H$9*L36 -> 0 | U36: =$H$8*L36 -> 14.020909 | V36: 0 | W36: 0 | X36: =$E$19*L36 -> 363.63636 | Y36: 0.25 | Z36: =R36*Y36 -> 1650.713 | AA36: =J36+N36 -> 1204.9 | AB36: =AA36/E36 -> 1204.9 | AD36: =R36+Z36 -> 8253.565 | AE36: 0.065 | AF36: =AD36*AE36 -> 536.48173 | AG36: 0.021 | AH36: =(R36*AG36) -> 138.65989 | AI36: 0.0965 | AJ36: =(R36*AI36) -> 637.17522 | AK36: =R36*9.65% -> 637.17522 | AL36: =(R36+U36+Z36+AF36+AH36+AJ36+W36)/0.96 -> 9979.0654 | AM36: 0.01 | AN36: =AL36*AM36 -> 99.790654 | AO36: =R36+T36+U36+X36+Z36+AF36+AH36+AJ36+W36+AN36 -> 10043.33 | AP36: =AO36/E36 -> 10043.33 | AR36: =AO36-AF36-AH36-AK36-AN36 -> 8631.2223 | AS36: =AR36+(E$22*L36)+($E$23*L36) -> 8631.2223 | AT36: =AS36/E36 -> 8631.2223 | AU36: ='EST. DE CUSTO - IMP. PRÓPRIA'!$H$68 -> 0.65174242 | AV36: =AS36/AU36 -> 13243.303 | AW36: ='EST. DE CUSTO - IMP. PRÓPRIA'!$F$63 -> 0.04 | AX36: =AV36*AW36 -> 529.73211 | AY36: =AV36*AE36 -> 860.81468 | AZ36: 0 | BA36: =AV36+AY36+AZ36 -> 14104.117 | BB36: =BA36/E36 -> 14104.117 | BD36: 0 | BE36: =BA36+BD36 -> 14104.117 | BF36: =BE36/E36 -> 14104.117
D37: =INVOICE!C13 -> 3 1/4 x 9 | E37: =INVOICE!D13 -> 1 | F37: TON | G37: =INVOICE!B13 -> Clavo con cabeza 19 x 36 | H37: =INVOICE!E13 -> 7317.00.90 | I37: =INVOICE!I13 -> 970 | J37: =E37*I37 -> 970 | K37: =INVOICE!H13 -> 1000 | L37: =K37/$H$6 -> 0.090909091 | M37: =J37*$H$7 -> 5315.6 | N37: =$D$7*L37 -> 234.9 | O37: =$E$7*L37 -> 1287.252 | P37: =$E$8*L37 -> 0 | Q37: =J37+N37 -> 1204.9 | R37: =M37+O37+P37 -> 6602.852 | T37: =$H$9*L37 -> 0 | U37: =$H$8*L37 -> 14.020909 | V37: 0 | W37: 0 | X37: =$E$19*L37 -> 363.63636 | Y37: 0.25 | Z37: =R37*Y37 -> 1650.713 | AA37: =J37+N37 -> 1204.9 | AB37: =AA37/E37 -> 1204.9 | AD37: =R37+Z37 -> 8253.565 | AE37: 0.065 | AF37: =AD37*AE37 -> 536.48173 | AG37: 0.021 | AH37: =(R37*AG37) -> 138.65989 | AI37: 0.0965 | AJ37: =(R37*AI37) -> 637.17522 | AK37: =R37*9.65% -> 637.17522 | AL37: =(R37+U37+Z37+AF37+AH37+AJ37+W37)/0.96 -> 9979.0654 | AM37: 0.01 | AN37: =AL37*AM37 -> 99.790654 | AO37: =R37+T37+U37+X37+Z37+AF37+AH37+AJ37+W37+AN37 -> 10043.33 | AP37: =AO37/E37 -> 10043.33 | AR37: =AO37-AF37-AH37-AK37-AN37 -> 8631.2223 | AS37: =AR37+(E$22*L37)+($E$23*L37) -> 8631.2223 | AT37: =AS37/E37 -> 8631.2223 | AU37: ='EST. DE CUSTO - IMP. PRÓPRIA'!$H$68 -> 0.65174242 | AV37: =AS37/AU37 -> 13243.303 | AW37: ='EST. DE CUSTO - IMP. PRÓPRIA'!$F$63 -> 0.04 | AX37: =AV37*AW37 -> 529.73211 | AY37: =AV37*AE37 -> 860.81468 | AZ37: 0 | BA37: =AV37+AY37+AZ37 -> 14104.117 | BB37: =BA37/E37 -> 14104.117 | BD37: 0 | BE37: =BA37+BD37 -> 14104.117 | BF37: =BE37/E37 -> 14104.117
E38: =SUM(E27:E37) -> 11 | J38: =SUM(J27:J37) -> 11300 | K38: =SUM(K27:K37) -> 11000 | L38: =SUM(L27:L37) -> 1 | M38: =SUM(M27:M37) -> 61924 | N38: =SUM(N27:N37) -> 2583.9 | O38: =SUM(O27:O37) -> 14159.772 | P38: =SUM(P27:P37) -> 0 | Q38: =SUM(Q27:Q37) -> 13883.9 | R38: =SUM(R27:R37) -> 76083.772 | T38: =SUM(T27:T37) -> 0 | U38: =SUM(U27:U37) -> 154.23 | W38: =SUM(W27:W37) -> 0 | X38: =SUM(X27:X37) -> 4000 | Z38: =SUM(Z27:Z37) -> 19020.943 | AD38: =SUM(AD27:AD37) -> 95104.715 | AF38: =SUM(AF27:AF37) -> 6181.8065 | AH38: =SUM(AH27:AH37) -> 1597.7592 | AJ38: =SUM(AJ27:AJ37) -> 7342.084 | AK38: =SUM(AK27:AK37) -> 7342.084 | AL38: =SUM(AL27:AL37) -> 114979.79 | AN38: =SUM(AN27:AN37) -> 1149.7979 | AO38: =SUM(AO27:AO37) -> 115530.39 | AR38: =SUM(AR27:AR37) -> 99258.945 | AS38: =SUM(AS27:AS37) -> 99258.945 | AV38: =SUM(AV27:AV37) -> 152297.81 | AX38: =SUM(AX27:AX37) -> 6091.9125 | AY38: =SUM(AY27:AY37) -> 9899.3578 | AZ38: =SUM(AZ27:AZ37) -> 0 | BA38: =SUM(BA27:BA37) -> 162197.17 | BD38: =SUM(BD27:BD37) -> 0 | BE38: =SUM(BE27:BE37) -> 162197.17

Sheet EST. DE CUSTO - IMP. PRÓPRIA
B2: ESTIMATIVA DE CUSTO - IMPORTAÇÃO PRÓPRIA
B7: Dados Cliente
B8: Cliente
B9: CNPJ
B10: Endereço
B12: Mercadoria / Dados Complementares
B13: Produto: | C13: Pregos
B15: Data do Câmbio | C15: Câmbio / USD | E15: Incoterms
C16: ='CUSTO MERCADORIA - IMP. PRÓPRIA'!H7 -> 5.48 | E16: FOB
B18: Valor Aduaneiro | G18: Valor U$ | H18: Valor R$
B19: Valor FOB | G19: ='CUSTO MERCADORIA - IMP. PRÓPRIA'!D6 -> 11300 | H19: =G19*C16 -> 61924
B20: Frete Internacional | G20: ='CUSTO MERCADORIA - IMP. PRÓPRIA'!D7 -> 2583.9 | H20: =G20*C16 -> 14159.772
B21: Seguro | G21: ='CUSTO MERCADORIA - IMP. PRÓPRIA'!D8 -> 0 | H21: =G21*C16 -> 0
B22: Total - Valor CIF | G22: =SUM(G19:G21) -> 13883.9 | H22: =SUM(H19:H21) -> 76083.772
B24: Tributos de Nacionalização | H24: Valor R$
B25: I.I. | H25: ='CUSTO MERCADORIA - IMP. PRÓPRIA'!Z38 -> 19020.943
B26: IPI-Imp. | H26: ='CUSTO MERCADORIA - IMP. PRÓPRIA'!AF38 -> 6181.8065
B27: PIS-Imp. | H27: ='CUSTO MERCADORIA - IMP. PRÓPRIA'!AH38 -> 1597.7592
B28: COFINS-Imp. | H28: ='CUSTO MERCADORIA - IMP. PRÓPRIA'!AJ38 -> 7342.084
B29: ICMS Antecipado | H29: ='CUSTO MERCADORIA - IMP. PRÓPRIA'!AN38 -> 1149.7979
B30: TX Siscomex | H30: ='CUSTO MERCADORIA - IMP. PRÓPRIA'!H8 -> 154.23
B31: Total Tributos de Nacionalização | H31: =SUM(H25:H30) -> 35446.621
B33: Lançamentos Custos Aduaneiros | H33: Valor R$
B34: Liberação | H34: ='CUSTO MERCADORIA - IMP. PRÓPRIA'!E13 -> 0
B35: Armazenagem | H35: ='CUSTO MERCADORIA - IMP. PRÓPRIA'!E14 -> 0
B36: Frete interno | H36: ='CUSTO MERCADORIA - IMP. PRÓPRIA'!E15 -> 0
B37: Taxa de Expediente | H37: ='CUSTO MERCADORIA - IMP. PRÓPRIA'!E17 -> 1000
B38: Despacho Aduaneiro | H38: ='CUSTO MERCADORIA - IMP. PRÓPRIA'!E16 -> 3000
B39: AFRMM | H39: ='CUSTO MERCADORIA - IMP. PRÓPRIA'!H9 -> 0
B40: Total Despesas Aduaneiras | H40: =SUM(H34:H39) -> 4000
B42: NF-e de Importação | H42: Valor R$
B43: Produto | H43: =H22 -> 76083.772
B44: I.I. | H44: =H25 -> 19020.943
B45: IPI-Imp. | H45: =H26 -> 6181.8065
B46: Outras Despesas | C46: PIS+COFINS+ICMS+TAXA SISCOMEX+AFRMM | H46: =H27+H28+H30+H39+H29 -> 10243.871
B47: NF-e Nacionalização | H47: =SUM(H43:H46) -> 111530.39
B49: Outras Despesas Operacionais | H49: Valor R$
B50: Pacote Logístico | H50: ='CUSTO MERCADORIA - IMP. PRÓPRIA'!E22 -> 0
B51: Royalties | H51: ='CUSTO MERCADORIA - IMP. PRÓPRIA'!E23 -> 0
B52: Total outras despesas operacionais | H52: =SUM(H50:H51) -> 0
...
